Workbook

Sheet Leia-me
A1: Due Diligence Assistant — template de análise (módulo 1)
A2: Receitas, margens e geração de caixa, com regras de dívida, capital de giro e consistência. Exemplo preenchido: Velmora (empresa fictícia 'limpa', para medir alarmes falsos).
A4: Como funciona | B4: Quatro folhas em cadeia, sempre separadas: Input (dados, cada linha com a fonte) → Métricas (fórmulas) → Regras (cada métrica comparada com um limite) → Red Flags (os alertas que dispararam). Nenhum número é estimado: tudo sai de fórmulas que pode abrir e conferir.
A5: Para analisar outra empresa | B5: 1) Na folha Input, substitua as células amarelas pelos dados da nova empresa e atualize a coluna Fonte. 2) Marque os documentos recebidos (Sim / Não). 3) Abra a folha Red Flags: os alertas aparecem sozinhos.
A6: Ajustar as regras | B6: Na folha Regras, altere os limites (coluna F) e a relevância (coluna O). As regras e os alertas recalculam de imediato.
A7: Rever os alertas | B7: Na folha Red Flags, marque cada alerta como Aceite, Descartado ou Pendente e escreva o porquê. O estado fica na linha: se mudar limites, confirme que os comentários continuam ao lado do alerta certo.
A8: O que a IA fará depois | B8: As regras dão a evidência e uma pergunta-modelo. No passo 3, a IA lê os alertas, explica cada um, junta os que contam a mesma história e escreve as perguntas finais e o memo de duas páginas. A IA não cria alertas nem faz contas.
A9: Cores | B9: Amarelo com texto azul: valores e escolhas que pode editar. Preto: fórmulas. Cinzento: célula sem dado para aquele ano.
A10: Limitações | B10: Empresa desenhada sem problemas plantados, para medir alarmes falsos. Foi criada por quem conhece as regras: zero alertas é um teste de sanidade, não uma medida independente.

Sheet Red Flags
A1: Red flags — módulo 1 (gerados pelas regras)
A2: Preenchido por fórmula. O analista revê cada alerta nas colunas amarelas: Aceite / Descartado / Pendente.
E3: ="Alertas: "&$N$3&" · Alta: "&COUNTIFS(Regras!M5:M24,"Sim",Regras!O5:O24,"Alta")&" · Média: "&COUNTIFS(Regras!M5:M24,"Sim",Regras!O5:O24,"Média")&" · Baixa: "&COUNTIFS(Regras!M5:M24,"Sim",Regras!O5:O24,"Baixa")&" · Por rever: "&($N$3-COUNTIF(K6:K25,"Aceite")-COUNTIF(K6:K25,"Descartado")) -> Alertas: 0 · Alta: 0 · Média: 0 · Baixa: 0 · Por rever: 0 | N3: =COUNTIF(Regras!M5:M24,"Sim") -> 0
A5: Nº | B5: Regra | C5: Área | D5: Anos | E5: Evidência (com fonte) | F5: Cálculo e regra disparada | G5: Ponto a investigar | H5: Relevância | I5: Pergunta para a empresa | J5: Documento a pedir | K5: Estado do revisor | L5: Comentário do revisor
A6: =IF(1<=$N$3,1,"") | B6: =IF($A6="","",INDEX(Regras!$A$5:$A$24,MATCH($A6,Regras!$P$5:$P$24,0))) | C6: =IF($A6="","",INDEX(Regras!$B$5:$B$24,MATCH($A6,Regras!$P$5:$P$24,0))) | D6: =IF($A6="","",INDEX(Regras!$N$5:$N$24,MATCH($A6,Regras!$P$5:$P$24,0))) | E6: =IF($A6="","",INDEX(Regras!$Q$5:$Q$24,MATCH($A6,Regras!$P$5:$P$24,0))) | F6: =IF($A6="","",INDEX(Regras!$D$5:$D$24,MATCH($A6,Regras!$P$5:$P$24,0))&CHAR(10)&"Regra: "&INDEX(Regras!$V$5:$V$24,MATCH($A6,Regras!$P$5:$P$24,0))) | G6: =IF($A6="","",INDEX(Regras!$R$5:$R$24,MATCH($A6,Regras!$P$5:$P$24,0))) | H6: =IF($A6="","",INDEX(Regras!$O$5:$O$24,MATCH($A6,Regras!$P$5:$P$24,0))) | I6: =IF($A6="","",INDEX(Regras!$S$5:$S$24,MATCH($A6,Regras!$P$5:$P$24,0))) | J6: =IF($A6="","",INDEX(Regras!$T$5:$T$24,MATCH($A6,Regras!$P$5:$P$24,0)))
A7: =IF(2<=$N$3,2,"") | B7: =IF($A7="","",INDEX(Regras!$A$5:$A$24,MATCH($A7,Regras!$P$5:$P$24,0))) | C7: =IF($A7="","",INDEX(Regras!$B$5:$B$24,MATCH($A7,Regras!$P$5:$P$24,0))) | D7: =IF($A7="","",INDEX(Regras!$N$5:$N$24,MATCH($A7,Regras!$P$5:$P$24,0))) | E7: =IF($A7="","",INDEX(Regras!$Q$5:$Q$24,MATCH($A7,Regras!$P$5:$P$24,0))) | F7: =IF($A7="","",INDEX(Regras!$D$5:$D$24,MATCH($A7,Regras!$P$5:$P$24,0))&CHAR(10)&"Regra: "&INDEX(Regras!$V$5:$V$24,MATCH($A7,Regras!$P$5:$P$24,0))) | G7: =IF($A7="","",INDEX(Regras!$R$5:$R$24,MATCH($A7,Regras!$P$5:$P$24,0))) | H7: =IF($A7="","",INDEX(Regras!$O$5:$O$24,MATCH($A7,Regras!$P$5:$P$24,0))) | I7: =IF($A7="","",INDEX(Regras!$S$5:$S$24,MATCH($A7,Regras!$P$5:$P$24,0))) | J7: =IF($A7="","",INDEX(Regras!$T$5:$T$24,MATCH($A7,Regras!$P$5:$P$24,0)))
A8: =IF(3<=$N$3,3,"") | B8: =IF($A8="","",INDEX(Regras!$A$5:$A$24,MATCH($A8,Regras!$P$5:$P$24,0))) | C8: =IF($A8="","",INDEX(Regras!$B$5:$B$24,MATCH($A8,Regras!$P$5:$P$24,0))) | D8: =IF($A8="","",INDEX(Regras!$N$5:$N$24,MATCH($A8,Regras!$P$5:$P$24,0))) | E8: =IF($A8="","",INDEX(Regras!$Q$5:$Q$24,MATCH($A8,Regras!$P$5:$P$24,0))) | F8: =IF($A8="","",INDEX(Regras!$D$5:$D$24,MATCH($A8,Regras!$P$5:$P$24,0))&CHAR(10)&"Regra: "&INDEX(Regras!$V$5:$V$24,MATCH($A8,Regras!$P$5:$P$24,0))) | G8: =IF($A8="","",INDEX(Regras!$R$5:$R$24,MATCH($A8,Regras!$P$5:$P$24,0))) | H8: =IF($A8="","",INDEX(Regras!$O$5:$O$24,MATCH($A8,Regras!$P$5:$P$24,0))) | I8: =IF($A8="","",INDEX(Regras!$S$5:$S$24,MATCH($A8,Regras!$P$5:$P$24,0))) | J8: =IF($A8="","",INDEX(Regras!$T$5:$T$24,MATCH($A8,Regras!$P$5:$P$24,0)))
A9: =IF(4<=$N$3,4,"") | B9: =IF($A9="","",INDEX(Regras!$A$5:$A$24,MATCH($A9,Regras!$P$5:$P$24,0))) | C9: =IF($A9="","",INDEX(Regras!$B$5:$B$24,MATCH($A9,Regras!$P$5:$P$24,0))) | D9: =IF($A9="","",INDEX(Regras!$N$5:$N$24,MATCH($A9,Regras!$P$5:$P$24,0))) | E9: =IF($A9="","",INDEX(Regras!$Q$5:$Q$24,MATCH($A9,Regras!$P$5:$P$24,0))) | F9: =IF($A9="","",INDEX(Regras!$D$5:$D$24,MATCH($A9,Regras!$P$5:$P$24,0))&CHAR(10)&"Regra: "&INDEX(Regras!$V$5:$V$24,MATCH($A9,Regras!$P$5:$P$24,0))) | G9: =IF($A9="","",INDEX(Regras!$R$5:$R$24,MATCH($A9,Regras!$P$5:$P$24,0))) | H9: =IF($A9="","",INDEX(Regras!$O$5:$O$24,MATCH($A9,Regras!$P$5:$P$24,0))) | I9: =IF($A9="","",INDEX(Regras!$S$5:$S$24,MATCH($A9,Regras!$P$5:$P$24,0))) | J9: =IF($A9="","",INDEX(Regras!$T$5:$T$24,MATCH($A9,Regras!$P$5:$P$24,0)))
A10: =IF(5<=$N$3,5,"") | B10: =IF($A10="","",INDEX(Regras!$A$5:$A$24,MATCH($A10,Regras!$P$5:$P$24,0))) | C10: =IF($A10="","",INDEX(Regras!$B$5:$B$24,MATCH($A10,Regras!$P$5:$P$24,0))) | D10: =IF($A10="","",INDEX(Regras!$N$5:$N$24,MATCH($A10,Regras!$P$5:$P$24,0))) | E10: =IF($A10="","",INDEX(Regras!$Q$5:$Q$24,MATCH($A10,Regras!$P$5:$P$24,0))) | F10: =IF($A10="","",INDEX(Regras!$D$5:$D$24,MATCH($A10,Regras!$P$5:$P$24,0))&CHAR(10)&"Regra: "&INDEX(Regras!$V$5:$V$24,MATCH($A10,Regras!$P$5:$P$24,0))) | G10: =IF($A10="","",INDEX(Regras!$R$5:$R$24,MATCH($A10,Regras!$P$5:$P$24,0))) | H10: =IF($A10="","",INDEX(Regras!$O$5:$O$24,MATCH($A10,Regras!$P$5:$P$24,0))) | I10: =IF($A10="","",INDEX(Regras!$S$5:$S$24,MATCH($A10,Regras!$P$5:$P$24,0))) | J10: =IF($A10="","",INDEX(Regras!$T$5:$T$24,MATCH($A10,Regras!$P$5:$P$24,0)))
A11: =IF(6<=$N$3,6,"") | B11: =IF($A11="","",INDEX(Regras!$A$5:$A$24,MATCH($A11,Regras!$P$5:$P$24,0))) | C11: =IF($A11="","",INDEX(Regras!$B$5:$B$24,MATCH($A11,Regras!$P$5:$P$24,0))) | D11: =IF($A11="","",INDEX(Regras!$N$5:$N$24,MATCH($A11,Regras!$P$5:$P$24,0))) | E11: =IF($A11="","",INDEX(Regras!$Q$5:$Q$24,MATCH($A11,Regras!$P$5:$P$24,0))) | F11: =IF($A11="","",INDEX(Regras!$D$5:$D$24,MATCH($A11,Regras!$P$5:$P$24,0))&CHAR(10)&"Regra: "&INDEX(Regras!$V$5:$V$24,MATCH($A11,Regras!$P$5:$P$24,0))) | G11: =IF($A11="","",INDEX(Regras!$R$5:$R$24,MATCH($A11,Regras!$P$5:$P$24,0))) | H11: =IF($A11="","",INDEX(Regras!$O$5:$O$24,MATCH($A11,Regras!$P$5:$P$24,0))) | I11: =IF($A11="","",INDEX(Regras!$S$5:$S$24,MATCH($A11,Regras!$P$5:$P$24,0))) | J11: =IF($A11="","",INDEX(Regras!$T$5:$T$24,MATCH($A11,Regras!$P$5:$P$24,0)))
A12: =IF(7<=$N$3,7,"") | B12: =IF($A12="","",INDEX(Regras!$A$5:$A$24,MATCH($A12,Regras!$P$5:$P$24,0))) | C12: =IF($A12="","",INDEX(Regras!$B$5:$B$24,MATCH($A12,Regras!$P$5:$P$24,0))) | D12: =IF($A12="","",INDEX(Regras!$N$5:$N$24,MATCH($A12,Regras!$P$5:$P$24,0))) | E12: =IF($A12="","",INDEX(Regras!$Q$5:$Q$24,MATCH($A12,Regras!$P$5:$P$24,0))) | F12: =IF($A12="","",INDEX(Regras!$D$5:$D$24,MATCH($A12,Regras!$P$5:$P$24,0))&CHAR(10)&"Regra: "&INDEX(Regras!$V$5:$V$24,MATCH($A12,Regras!$P$5:$P$24,0))) | G12: =IF($A12="","",INDEX(Regras!$R$5:$R$24,MATCH($A12,Regras!$P$5:$P$24,0))) | H12: =IF($A12="","",INDEX(Regras!$O$5:$O$24,MATCH($A12,Regras!$P$5:$P$24,0))) | I12: =IF($A12="","",INDEX(Regras!$S$5:$S$24,MATCH($A12,Regras!$P$5:$P$24,0))) | J12: =IF($A12="","",INDEX(Regras!$T$5:$T$24,MATCH($A12,Regras!$P$5:$P$24,0)))
A13: =IF(8<=$N$3,8,"") | B13: =IF($A13="","",INDEX(Regras!$A$5:$A$24,MATCH($A13,Regras!$P$5:$P$24,0))) | C13: =IF($A13="","",INDEX(Regras!$B$5:$B$24,MATCH($A13,Regras!$P$5:$P$24,0))) | D13: =IF($A13="","",INDEX(Regras!$N$5:$N$24,MATCH($A13,Regras!$P$5:$P$24,0))) | E13: =IF($A13="","",INDEX(Regras!$Q$5:$Q$24,MATCH($A13,Regras!$P$5:$P$24,0))) | F13: =IF($A13="","",INDEX(Regras!$D$5:$D$24,MATCH($A13,Regras!$P$5:$P$24,0))&CHAR(10)&"Regra: "&INDEX(Regras!$V$5:$V$24,MATCH($A13,Regras!$P$5:$P$24,0))) | G13: =IF($A13="","",INDEX(Regras!$R$5:$R$24,MATCH($A13,Regras!$P$5:$P$24,0))) | H13: =IF($A13="","",INDEX(Regras!$O$5:$O$24,MATCH($A13,Regras!$P$5:$P$24,0))) | I13: =IF($A13="","",INDEX(Regras!$S$5:$S$24,MATCH($A13,Regras!$P$5:$P$24,0))) | J13: =IF($A13="","",INDEX(Regras!$T$5:$T$24,MATCH($A13,Regras!$P$5:$P$24,0)))
A14: =IF(9<=$N$3,9,"") | B14: =IF($A14="","",INDEX(Regras!$A$5:$A$24,MATCH($A14,Regras!$P$5:$P$24,0))) | C14: =IF($A14="","",INDEX(Regras!$B$5:$B$24,MATCH($A14,Regras!$P$5:$P$24,0))) | D14: =IF($A14="","",INDEX(Regras!$N$5:$N$24,MATCH($A14,Regras!$P$5:$P$24,0))) | E14: =IF($A14="","",INDEX(Regras!$Q$5:$Q$24,MATCH($A14,Regras!$P$5:$P$24,0))) | F14: =IF($A14="","",INDEX(Regras!$D$5:$D$24,MATCH($A14,Regras!$P$5:$P$24,0))&CHAR(10)&"Regra: "&INDEX(Regras!$V$5:$V$24,MATCH($A14,Regras!$P$5:$P$24,0))) | G14: =IF($A14="","",INDEX(Regras!$R$5:$R$24,MATCH($A14,Regras!$P$5:$P$24,0))) | H14: =IF($A14="","",INDEX(Regras!$O$5:$O$24,MATCH($A14,Regras!$P$5:$P$24,0))) | I14: =IF($A14="","",INDEX(Regras!$S$5:$S$24,MATCH($A14,Regras!$P$5:$P$24,0))) | J14: =IF($A14="","",INDEX(Regras!$T$5:$T$24,MATCH($A14,Regras!$P$5:$P$24,0)))
A15: =IF(10<=$N$3,10,"") | B15: =IF($A15="","",INDEX(Regras!$A$5:$A$24,MATCH($A15,Regras!$P$5:$P$24,0))) | C15: =IF($A15="","",INDEX(Regras!$B$5:$B$24,MATCH($A15,Regras!$P$5:$P$24,0))) | D15: =IF($A15="","",INDEX(Regras!$N$5:$N$24,MATCH($A15,Regras!$P$5:$P$24,0))) | E15: =IF($A15="","",INDEX(Regras!$Q$5:$Q$24,MATCH($A15,Regras!$P$5:$P$24,0))) | F15: =IF($A15="","",INDEX(Regras!$D$5:$D$24,MATCH($A15,Regras!$P$5:$P$24,0))&CHAR(10)&"Regra: "&INDEX(Regras!$V$5:$V$24,MATCH($A15,Regras!$P$5:$P$24,0))) | G15: =IF($A15="","",INDEX(Regras!$R$5:$R$24,MATCH($A15,Regras!$P$5:$P$24,0))) | H15: =IF($A15="","",INDEX(Regras!$O$5:$O$24,MATCH($A15,Regras!$P$5:$P$24,0))) | I15: =IF($A15="","",INDEX(Regras!$S$5:$S$24,MATCH($A15,Regras!$P$5:$P$24,0))) | J15: =IF($A15="","",INDEX(Regras!$T$5:$T$24,MATCH($A15,Regras!$P$5:$P$24,0)))
A16: =IF(11<=$N$3,11,"") | B16: =IF($A16="","",INDEX(Regras!$A$5:$A$24,MATCH($A16,Regras!$P$5:$P$24,0))) | C16: =IF($A16="","",INDEX(Regras!$B$5:$B$24,MATCH($A16,Regras!$P$5:$P$24,0))) | D16: =IF($A16="","",INDEX(Regras!$N$5:$N$24,MATCH($A16,Regras!$P$5:$P$24,0))) | E16: =IF($A16="","",INDEX(Regras!$Q$5:$Q$24,MATCH($A16,Regras!$P$5:$P$24,0))) | F16: =IF($A16="","",INDEX(Regras!$D$5:$D$24,MATCH($A16,Regras!$P$5:$P$24,0))&CHAR(10)&"Regra: "&INDEX(Regras!$V$5:$V$24,MATCH($A16,Regras!$P$5:$P$24,0))) | G16: =IF($A16="","",INDEX(Regras!$R$5:$R$24,MATCH($A16,Regras!$P$5:$P$24,0))) | H16: =IF($A16="","",INDEX(Regras!$O$5:$O$24,MATCH($A16,Regras!$P$5:$P$24,0))) | I16: =IF($A16="","",INDEX(Regras!$S$5:$S$24,MATCH($A16,Regras!$P$5:$P$24,0))) | J16: =IF($A16="","",INDEX(Regras!$T$5:$T$24,MATCH($A16,Regras!$P$5:$P$24,0)))
A17: =IF(12<=$N$3,12,"") | B17: =IF($A17="","",INDEX(Regras!$A$5:$A$24,MATCH($A17,Regras!$P$5:$P$24,0))) | C17: =IF($A17="","",INDEX(Regras!$B$5:$B$24,MATCH($A17,Regras!$P$5:$P$24,0))) | D17: =IF($A17="","",INDEX(Regras!$N$5:$N$24,MATCH($A17,Regras!$P$5:$P$24,0))) | E17: =IF($A17="","",INDEX(Regras!$Q$5:$Q$24,MATCH($A17,Regras!$P$5:$P$24,0))) | F17: =IF($A17="","",INDEX(Regras!$D$5:$D$24,MATCH($A17,Regras!$P$5:$P$24,0))&CHAR(10)&"Regra: "&INDEX(Regras!$V$5:$V$24,MATCH($A17,Regras!$P$5:$P$24,0))) | G17: =IF($A17="","",INDEX(Regras!$R$5:$R$24,MATCH($A17,Regras!$P$5:$P$24,0))) | H17: =IF($A17="","",INDEX(Regras!$O$5:$O$24,MATCH($A17,Regras!$P$5:$P$24,0))) | I17: =IF($A17="","",INDEX(Regras!$S$5:$S$24,MATCH($A17,Regras!$P$5:$P$24,0))) | J17: =IF($A17="","",INDEX(Regras!$T$5:$T$24,MATCH($A17,Regras!$P$5:$P$24,0)))
A18: =IF(13<=$N$3,13,"") | B18: =IF($A18="","",INDEX(Regras!$A$5:$A$24,MATCH($A18,Regras!$P$5:$P$24,0))) | C18: =IF($A18="","",INDEX(Regras!$B$5:$B$24,MATCH($A18,Regras!$P$5:$P$24,0))) | D18: =IF($A18="","",INDEX(Regras!$N$5:$N$24,MATCH($A18,Regras!$P$5:$P$24,0))) | E18: =IF($A18="","",INDEX(Regras!$Q$5:$Q$24,MATCH($A18,Regras!$P$5:$P$24,0))) | F18: =IF($A18="","",INDEX(Regras!$D$5:$D$24,MATCH($A18,Regras!$P$5:$P$24,0))&CHAR(10)&"Regra: "&INDEX(Regras!$V$5:$V$24,MATCH($A18,Regras!$P$5:$P$24,0))) | G18: =IF($A18="","",INDEX(Regras!$R$5:$R$24,MATCH($A18,Regras!$P$5:$P$24,0))) | H18: =IF($A18="","",INDEX(Regras!$O$5:$O$24,MATCH($A18,Regras!$P$5:$P$24,0))) | I18: =IF($A18="","",INDEX(Regras!$S$5:$S$24,MATCH($A18,Regras!$P$5:$P$24,0))) | J18: =IF($A18="","",INDEX(Regras!$T$5:$T$24,MATCH($A18,Regras!$P$5:$P$24,0)))
A19: =IF(14<=$N$3,14,"") | B19: =IF($A19="","",INDEX(Regras!$A$5:$A$24,MATCH($A19,Regras!$P$5:$P$24,0))) | C19: =IF($A19="","",INDEX(Regras!$B$5:$B$24,MATCH($A19,Regras!$P$5:$P$24,0))) | D19: =IF($A19="","",INDEX(Regras!$N$5:$N$24,MATCH($A19,Regras!$P$5:$P$24,0))) | E19: =IF($A19="","",INDEX(Regras!$Q$5:$Q$24,MATCH($A19,Regras!$P$5:$P$24,0))) | F19: =IF($A19="","",INDEX(Regras!$D$5:$D$24,MATCH($A19,Regras!$P$5:$P$24,0))&CHAR(10)&"Regra: "&INDEX(Regras!$V$5:$V$24,MATCH($A19,Regras!$P$5:$P$24,0))) | G19: =IF($A19="","",INDEX(Regras!$R$5:$R$24,MATCH($A19,Regras!$P$5:$P$24,0))) | H19: =IF($A19="","",INDEX(Regras!$O$5:$O$24,MATCH($A19,Regras!$P$5:$P$24,0))) | I19: =IF($A19="","",INDEX(Regras!$S$5:$S$24,MATCH($A19,Regras!$P$5:$P$24,0))) | J19: =IF($A19="","",INDEX(Regras!$T$5:$T$24,MATCH($A19,Regras!$P$5:$P$24,0)))
A20: =IF(15<=$N$3,15,"") | B20: =IF($A20="","",INDEX(Regras!$A$5:$A$24,MATCH($A20,Regras!$P$5:$P$24,0))) | C20: =IF($A20="","",INDEX(Regras!$B$5:$B$24,MATCH($A20,Regras!$P$5:$P$24,0))) | D20: =IF($A20="","",INDEX(Regras!$N$5:$N$24,MATCH($A20,Regras!$P$5:$P$24,0))) | E20: =IF($A20="","",INDEX(Regras!$Q$5:$Q$24,MATCH($A20,Regras!$P$5:$P$24,0))) | F20: =IF($A20="","",INDEX(Regras!$D$5:$D$24,MATCH($A20,Regras!$P$5:$P$24,0))&CHAR(10)&"Regra: "&INDEX(Regras!$V$5:$V$24,MATCH($A20,Regras!$P$5:$P$24,0))) | G20: =IF($A20="","",INDEX(Regras!$R$5:$R$24,MATCH($A20,Regras!$P$5:$P$24,0))) | H20: =IF($A20="","",INDEX(Regras!$O$5:$O$24,MATCH($A20,Regras!$P$5:$P$24,0))) | I20: =IF($A20="","",INDEX(Regras!$S$5:$S$24,MATCH($A20,Regras!$P$5:$P$24,0))) | J20: =IF($A20="","",INDEX(Regras!$T$5:$T$24,MATCH($A20,Regras!$P$5:$P$24,0)))
A21: =IF(16<=$N$3,16,"") | B21: =IF($A21="","",INDEX(Regras!$A$5:$A$24,MATCH($A21,Regras!$P$5:$P$24,0))) | C21: =IF($A21="","",INDEX(Regras!$B$5:$B$24,MATCH($A21,Regras!$P$5:$P$24,0))) | D21: =IF($A21="","",INDEX(Regras!$N$5:$N$24,MATCH($A21,Regras!$P$5:$P$24,0))) | E21: =IF($A21="","",INDEX(Regras!$Q$5:$Q$24,MATCH($A21,Regras!$P$5:$P$24,0))) | F21: =IF($A21="","",INDEX(Regras!$D$5:$D$24,MATCH($A21,Regras!$P$5:$P$24,0))&CHAR(10)&"Regra: "&INDEX(Regras!$V$5:$V$24,MATCH($A21,Regras!$P$5:$P$24,0))) | G21: =IF($A21="","",INDEX(Regras!$R$5:$R$24,MATCH($A21,Regras!$P$5:$P$24,0))) | H21: =IF($A21="","",INDEX(Regras!$O$5:$O$24,MATCH($A21,Regras!$P$5:$P$24,0))) | I21: =IF($A21="","",INDEX(Regras!$S$5:$S$24,MATCH($A21,Regras!$P$5:$P$24,0))) | J21: =IF($A21="","",INDEX(Regras!$T$5:$T$24,MATCH($A21,Regras!$P$5:$P$24,0)))
A22: =IF(17<=$N$3,17,"") | B22: =IF($A22="","",INDEX(Regras!$A$5:$A$24,MATCH($A22,Regras!$P$5:$P$24,0))) | C22: =IF($A22="","",INDEX(Regras!$B$5:$B$24,MATCH($A22,Regras!$P$5:$P$24,0))) | D22: =IF($A22="","",INDEX(Regras!$N$5:$N$24,MATCH($A22,Regras!$P$5:$P$24,0))) | E22: =IF($A22="","",INDEX(Regras!$Q$5:$Q$24,MATCH($A22,Regras!$P$5:$P$24,0))) | F22: =IF($A22="","",INDEX(Regras!$D$5:$D$24,MATCH($A22,Regras!$P$5:$P$24,0))&CHAR(10)&"Regra: "&INDEX(Regras!$V$5:$V$24,MATCH($A22,Regras!$P$5:$P$24,0))) | G22: =IF($A22="","",INDEX(Regras!$R$5:$R$24,MATCH($A22,Regras!$P$5:$P$24,0))) | H22: =IF($A22="","",INDEX(Regras!$O$5:$O$24,MATCH($A22,Regras!$P$5:$P$24,0))) | I22: =IF($A22="","",INDEX(Regras!$S$5:$S$24,MATCH($A22,Regras!$P$5:$P$24,0))) | J22: =IF($A22="","",INDEX(Regras!$T$5:$T$24,MATCH($A22,Regras!$P$5:$P$24,0)))
A23: =IF(18<=$N$3,18,"") | B23: =IF($A23="","",INDEX(Regras!$A$5:$A$24,MATCH($A23,Regras!$P$5:$P$24,0))) | C23: =IF($A23="","",INDEX(Regras!$B$5:$B$24,MATCH($A23,Regras!$P$5:$P$24,0))) | D23: =IF($A23="","",INDEX(Regras!$N$5:$N$24,MATCH($A23,Regras!$P$5:$P$24,0))) | E23: =IF($A23="","",INDEX(Regras!$Q$5:$Q$24,MATCH($A23,Regras!$P$5:$P$24,0))) | F23: =IF($A23="","",INDEX(Regras!$D$5:$D$24,MATCH($A23,Regras!$P$5:$P$24,0))&CHAR(10)&"Regra: "&INDEX(Regras!$V$5:$V$24,MATCH($A23,Regras!$P$5:$P$24,0))) | G23: =IF($A23="","",INDEX(Regras!$R$5:$R$24,MATCH($A23,Regras!$P$5:$P$24,0))) | H23: =IF($A23="","",INDEX(Regras!$O$5:$O$24,MATCH($A23,Regras!$P$5:$P$24,0))) | I23: =IF($A23="","",INDEX(Regras!$S$5:$S$24,MATCH($A23,Regras!$P$5:$P$24,0))) | J23: =IF($A23="","",INDEX(Regras!$T$5:$T$24,MATCH($A23,Regras!$P$5:$P$24,0)))
A24: =IF(19<=$N$3,19,"") | B24: =IF($A24="","",INDEX(Regras!$A$5:$A$24,MATCH($A24,Regras!$P$5:$P$24,0))) | C24: =IF($A24="","",INDEX(Regras!$B$5:$B$24,MATCH($A24,Regras!$P$5:$P$24,0))) | D24: =IF($A24="","",INDEX(Regras!$N$5:$N$24,MATCH($A24,Regras!$P$5:$P$24,0))) | E24: =IF($A24="","",INDEX(Regras!$Q$5:$Q$24,MATCH($A24,Regras!$P$5:$P$24,0))) | F24: =IF($A24="","",INDEX(Regras!$D$5:$D$24,MATCH($A24,Regras!$P$5:$P$24,0))&CHAR(10)&"Regra: "&INDEX(Regras!$V$5:$V$24,MATCH($A24,Regras!$P$5:$P$24,0))) | G24: =IF($A24="","",INDEX(Regras!$R$5:$R$24,MATCH($A24,Regras!$P$5:$P$24,0))) | H24: =IF($A24="","",INDEX(Regras!$O$5:$O$24,MATCH($A24,Regras!$P$5:$P$24,0))) | I24: =IF($A24="","",INDEX(Regras!$S$5:$S$24,MATCH($A24,Regras!$P$5:$P$24,0))) | J24: =IF($A24="","",INDEX(Regras!$T$5:$T$24,MATCH($A24,Regras!$P$5:$P$24,0)))
A25: =IF(20<=$N$3,20,"") | B25: =IF($A25="","",INDEX(Regras!$A$5:$A$24,MATCH($A25,Regras!$P$5:$P$24,0))) | C25: =IF($A25="","",INDEX(Regras!$B$5:$B$24,MATCH($A25,Regras!$P$5:$P$24,0))) | D25: =IF($A25="","",INDEX(Regras!$N$5:$N$24,MATCH($A25,Regras!$P$5:$P$24,0))) | E25: =IF($A25="","",INDEX(Regras!$Q$5:$Q$24,MATCH($A25,Regras!$P$5:$P$24,0))) | F25: =IF($A25="","",INDEX(Regras!$D$5:$D$24,MATCH($A25,Regras!$P$5:$P$24,0))&CHAR(10)&"Regra: "&INDEX(Regras!$V$5:$V$24,MATCH($A25,Regras!$P$5:$P$24,0))) | G25: =IF($A25="","",INDEX(Regras!$R$5:$R$24,MATCH($A25,Regras!$P$5:$P$24,0))) | H25: =IF($A25="","",INDEX(Regras!$O$5:$O$24,MATCH($A25,Regras!$P$5:$P$24,0))) | I25: =IF($A25="","",INDEX(Regras!$S$5:$S$24,MATCH($A25,Regras!$P$5:$P$24,0))) | J25: =IF($A25="","",INDEX(Regras!$T$5:$T$24,MATCH($A25,Regras!$P$5:$P$24,0)))

Sheet Input
A1: Input — dados da empresa-alvo
A2: € milhares. Preencha só as células amarelas (azul = valor copiado do data room). A coluna Fonte guarda a origem de cada linha.
A4: Rubrica | B4: 2022 | C4: 2023 | D4: 2024 | E4: 2025 | F4: Fonte no data room
A5: Demonstração de resultados (gastos com sinal negativo)
A6: Vendas e serviços prestados | C6: 15200 | D6: 15900 | E6: 16700 | F6: DRE!B5:D5
A7: Custo das mercadorias vendidas (CMV) | C7: -10944 | D7: -11385 | E7: -12041 | F7: DRE!B6:D6
A8: Fornecimentos e serviços externos | C8: -1520 | D8: -1580 | E8: -1650 | F8: DRE!B8:D8
A9: Gastos com o pessoal | C9: -1410 | D9: -1470 | E9: -1540 | F9: DRE!B9:D9
A10: Imparidade de dívidas a receber | C10: -30 | D10: -35 | E10: -35 | F10: DRE!B10:D10
A11: Outros rendimentos | C11: 60 | D11: 55 | E11: 65 | F11: DRE!B11:D11
A12: Outros gastos | C12: -40 | D12: -45 | E12: -50 | F12: DRE!B12:D12
A13: Depreciações e amortizações | C13: -290 | D13: -300 | E13: -315 | F13: DRE!B14:D14
A14: Juros e gastos similares | C14: -105 | D14: -90 | E14: -70 | F14: DRE!B16:D16
A15: Imposto sobre o rendimento | C15: -207 | D15: -236 | E15: -239 | F15: DRE!B18:D18
A16: Resultado líquido (DRE) | C16: 714 | D16: 814 | E16: 825 | F16: DRE!B19:D19
A18: Balanço (31 de dezembro)
A19: Ativos fixos tangíveis | B19: 2900 | C19: 2940 | D19: 2990 | E19: 3040 | F19: Balanço!B6:E6
A20: Outros ativos não correntes | B20: 0 | C20: 0 | D20: 0 | E20: 0 | F20: Não existe no data room (0)
A21: Inventários | B21: 2170 | C21: 2250 | D21: 2340 | E21: 2470 | F21: Balanço!B8:E8
A22: Clientes | B22: 2480 | C22: 2582 | D22: 2700 | E22: 2840 | F22: Balanço!B9:E9
A23: Outros ativos correntes | B23: 240 | C23: 250 | D23: 255 | E23: 265 | F23: Balanço!B10:E10
A24: Caixa e depósitos bancários | B24: 700 | C24: 642 | D24: 618 | E24: 553 | F24: Balanço!B11:E11
A25: Total do capital próprio | B25: 3860 | C25: 4324 | D25: 4838 | E25: 5333 | F25: Balanço!B19:E19
A26: Resultado líquido (balanço) | B26: 650 | C26: 714 | D26: 814 | E26: 825 | F26: Balanço!B18:E18
A27: Financiamentos obtidos (não corrente) | B27: 2040 | C27: 1680 | D27: 1320 | E27: 960 | F27: Balanço!B20:E20
A28: Outros passivos não correntes | B28: 0 | C28: 0 | D28: 0 | E28: 0 | F28: Não existe no data room (0)
A29: Fornecedores | B29: 1750 | C29: 1800 | D29: 1870 | E29: 1980 | F29: Balanço!B22:E22
A30: Financiamentos obtidos (corrente) | B30: 360 | C30: 360 | D30: 360 | E30: 360 | F30: Balanço!B23:E23
A31: Outros passivos correntes | B31: 480 | C31: 500 | D31: 515 | E31: 535 | F31: Balanço!B24:E24
A33: Demonstração de fluxos de caixa
A34: Resultado líquido (DFC) | C34: 714 | D34: 814 | E34: 825 | F34: DFC!B5:D5
A35: Variação de clientes | C35: -102 | D35: -118 | E35: -140 | F35: DFC!B10:D10
A36: Variação de inventários | C36: -80 | D36: -90 | E36: -130 | F36: DFC!B11:D11
A37: Variação de fornecedores | C37: 50 | D37: 70 | E37: 110 | F37: DFC!B12:D12
A38: Variação de outros ativos correntes | C38: -10 | D38: -5 | E38: -10 | F38: DFC!B13:D13
A39: Variação de outros passivos correntes | C39: 20 | D39: 15 | E39: 20 | F39: DFC!B14:D14
A40: Caixa gerada pelas operações (antes de juros e impostos) | C40: 1194 | D40: 1312 | E40: 1294 | F40: DFC!B15:D15
A41: Fluxo de caixa das atividades operacionais (FCO) | C41: 882 | D41: 986 | E41: 985 | F41: DFC!B18:D18
A42: Pagamentos de ativos fixos (capex) | C42: -330 | D42: -350 | E42: -380 | F42: DFC!B20:D20
A43: Recebimentos da alienação de ativos fixos | C43: 0 | D43: 0 | E43: 20 | F43: DFC!B21:D21
...

Sheet Métricas
A1: Métricas — calculadas por fórmula a partir do Input
A2: Não editar. 'n.d.' = não disponível (falta o ano anterior ou o dado).
A4: Métrica | B4: 2022 | C4: 2023 | D4: 2024 | E4: 2025 | F4: Como se calcula
A5: Receitas
A6: Vendas | C6: =Input!C6 -> 15200 | D6: =Input!D6 -> 15900 | E6: =Input!E6 -> 16700 | F6: Input
A7: Crescimento das vendas | C7: n.d. | D7: =D6/C6-1 -> 0.046052632 | E7: =E6/D6-1 -> 0.050314465 | F7: Vendas do ano / vendas do ano anterior − 1
A8: Vendas a clientes novos | C8: n.d. | D8: =SUM(D69:D80) -> 230 | E8: =SUM(E69:E80) -> 0 | F8: Clientes sem vendas no ano anterior
A9: Clientes novos (% das vendas) | C9: n.d. | D9: =D8/D6 -> 0.014465409 | E9: =E8/E6 -> 0 | F9: Vendas a clientes novos / vendas
A10: Maior cliente novo | C10: n.d. | D10: =IF(D8=0,"—",INDEX($A$69:$A$80,MATCH(MAX(D69:D80),D69:D80,0))) -> Cliente J | E10: =IF(E8=0,"—",INDEX($A$69:$A$80,MATCH(MAX(E69:E80),E69:E80,0))) -> — | F10: Nome do cliente novo com mais vendas
A11: Crescimento das vendas sem clientes novos | C11: n.d. | D11: =(D6-D8)/C6-1 -> 0.030921053 | E11: =(E6-E8)/D6-1 -> 0.050314465 | F11: (Vendas − vendas a clientes novos) / vendas do ano anterior − 1
A12: Maior cliente (% das vendas) | C12: =MAX(Input!C49:C60)/C6 -> 0.15460526 | D12: =MAX(Input!D49:D60)/D6 -> 0.15597484 | E12: =MAX(Input!E49:E60)/E6 -> 0.15688623 | F12: Vendas do maior cliente / vendas
A13: Maior cliente | C13: =INDEX(Input!$A$49:$A$60,MATCH(MAX(Input!C49:C60),Input!C49:C60,0)) -> Cliente A | D13: =INDEX(Input!$A$49:$A$60,MATCH(MAX(Input!D49:D60),Input!D49:D60,0)) -> Cliente A | E13: =INDEX(Input!$A$49:$A$60,MATCH(MAX(Input!E49:E60),Input!E49:E60,0)) -> Cliente A | F13: Nome do cliente com mais vendas
A14: Vendas sem o maior cliente e sem clientes novos | C14: =C6-MAX(Input!C49:C60) -> 12850 | D14: =D6-MAX(Input!D49:D60)-D8 -> 13190 | E14: =E6-MAX(Input!E49:E60)-E8 -> 14080 | F14: Vendas − maior cliente − clientes novos (2023: só sem o maior cliente)
A15: Crescimento das vendas sem o maior cliente e sem novos | C15: n.d. | D15: =D14/C14-1 -> 0.026459144 | E15: =E14/D14-1 -> 0.06747536 | F15: Mostra se o resto da carteira cresce
A16: Margens e qualidade do EBITDA
A17: Margem bruta | C17: =(Input!C6+Input!C7)/C6 -> 0.28 | D17: =(Input!D6+Input!D7)/D6 -> 0.28396226 | E17: =(Input!E6+Input!E7)/E6 -> 0.27898204 | F17: (Vendas + CMV) / vendas
A18: Variação da margem bruta | C18: n.d. | D18: =(D17-C17)*100 -> 0.39622642 | E18: =(E17-D17)*100 -> -0.49802282 | F18: Margem do ano − margem do ano anterior, em pontos percentuais
A19: EBITDA reportado | C19: =SUM(Input!C6:C12) -> 1316 | D19: =SUM(Input!D6:D12) -> 1440 | E19: =SUM(Input!E6:E12) -> 1449 | F19: Vendas + CMV + FSE + pessoal + imparidades + outros rendimentos + outros gastos
A20: Margem EBITDA | C20: =C19/C6 -> 0.086578947 | D20: =D19/D6 -> 0.090566038 | E20: =E19/E6 -> 0.086766467 | F20: EBITDA / vendas
A21: Outros rendimentos (% das vendas) | C21: =Input!C11/C6 -> 0.0039473684 | D21: =Input!D11/D6 -> 0.0034591195 | E21: =Input!E11/E6 -> 0.0038922156 | F21: Outros rendimentos / vendas
A22: Variação dos outros rendimentos | C22: n.d. | D22: =IF(Input!C11=0,"n.d.",Input!D11/Input!C11-1) -> -0.083333333 | E22: =IF(Input!D11=0,"n.d.",Input!E11/Input!D11-1) -> 0.18181818 | F22: Outros rendimentos / ano anterior − 1
A23: Ganhos na alienação de ativos (dentro do EBITDA) | C23: =-Input!C44 -> 0 | D23: =-Input!D44 -> 0 | E23: =-Input!E44 -> 5 | F23: Sinal trocado da linha da DFC. Assume que o ganho está em Outros rendimentos, como manda o SNC
A24: Ganhos na alienação (% do EBITDA) | C24: =IF(C19<=0,"n.d.",C23/C19) -> 0 | D24: =IF(D19<=0,"n.d.",D23/D19) -> 0 | E24: =IF(E19<=0,"n.d.",E23/E19) -> 0.0034506556 | F24: Ganhos na alienação / EBITDA reportado
A25: EBITDA sem ganhos na alienação | C25: =C19-C23 -> 1316 | D25: =D19-D23 -> 1440 | E25: =E19-E23 -> 1444 | F25: EBITDA reportado − ganhos na alienação
A26: Ajustes da gestão ao EBITDA | C26: =SUM(Input!C64:C68) -> 25 | D26: =SUM(Input!D64:D68) -> 35 | E26: =SUM(Input!E64:E68) -> 40 | F26: Soma dos ajustes no Input
A27: EBITDA ajustado (gestão) | C27: =C19+C26 -> 1341 | D27: =D19+D26 -> 1475 | E27: =E19+E26 -> 1489 | F27: EBITDA reportado + ajustes
A28: Ajustes (% do EBITDA reportado) | C28: =IF(C19<=0,"n.d.",C26/C19) -> 0.01899696 | D28: =IF(D19<=0,"n.d.",D26/D19) -> 0.024305556 | E28: =IF(E19<=0,"n.d.",E26/E19) -> 0.027605245 | F28: Ajustes / EBITDA reportado
A29: Ajustes 'não recorrentes' presentes nos 3 anos | C29: n.d. | D29: n.d. | E29: =SUM(E83:E87) -> 0 | F29: Nº de linhas de ajuste com valor em 2023, 2024 e 2025
A30: Exemplo de ajuste repetido | C30: n.d. | D30: n.d. | E30: =IF(E29=0,"—",INDEX($A$83:$A$87,MATCH(1,E83:E87,0))) -> — | F30: Primeiro ajuste que se repete nos 3 anos
A31: Capital de giro
A32: Crescimento de clientes (contas a receber) | C32: =Input!C22/Input!B22-1 -> 0.041129032 | D32: =Input!D22/Input!C22-1 -> 0.045701007 | E32: =Input!E22/Input!D22-1 -> 0.051851852 | F32: Clientes / ano anterior − 1
A33: Clientes vs. vendas (diferença de crescimento) | C33: n.d. | D33: =(D32-D7)*100 -> -0.035162461 | E33: =(E32-E7)*100 -> 0.15373864 | F33: Crescimento de clientes − crescimento das vendas, em p.p.
A34: DSO (prazo médio de recebimento) | C34: =Input!C22/C6*365 -> 62.001974 | D34: =Input!D22/D6*365 -> 61.981132 | E34: =Input!E22/E6*365 -> 62.071856 | F34: Clientes / vendas × 365
A35: Variação do DSO | C35: n.d. | D35: =D34-C34 -> -0.020841609 | E35: =E34-D34 -> 0.090724212 | F35: DSO − DSO do ano anterior
A36: Crescimento dos inventários | C36: =Input!C21/Input!B21-1 -> 0.036866359 | D36: =Input!D21/Input!C21-1 -> 0.04 | E36: =Input!E21/Input!D21-1 -> 0.055555556 | F36: Inventários / ano anterior − 1
A37: Crescimento do CMV | C37: n.d. | D37: =Input!D7/Input!C7-1 -> 0.040296053 | E37: =Input!E7/Input!D7-1 -> 0.057619675 | F37: CMV / ano anterior − 1
A38: Inventários vs. CMV (diferença de crescimento) | C38: n.d. | D38: =(D36-D37)*100 -> -0.029605263 | E38: =(E36-E37)*100 -> -0.20641195 | F38: Crescimento dos inventários − crescimento do CMV, em p.p.
A39: DIO (dias de stock) | C39: =Input!C21/-Input!C7*365 -> 75.041118 | D39: =Input!D21/-Input!D7*365 -> 75.019763 | E39: =Input!E21/-Input!E7*365 -> 74.873349 | F39: Inventários / CMV × 365
A40: DPO (prazo médio de pagamento) | C40: =Input!C29/-Input!C7*365 -> 60.032895 | D40: =Input!D29/-Input!D7*365 -> 59.951691 | E40: =Input!E29/-Input!E7*365 -> 60.019932 | F40: Fornecedores / CMV × 365
A41: Variação do DPO | C41: n.d. | D41: =D40-C40 -> -0.081203916 | E41: =E40-D40 -> 0.068241078 | F41: DPO − DPO do ano anterior
...

Sheet Regras
A1: Catálogo de regras
A2: Cada regra compara uma métrica com um limite. Os limites (amarelo) são editáveis. Os alertas vão para a folha Red Flags.
A4: ID | B4: Área | C4: Regra | D4: Cálculo | E4: Condição | F4: Limite | G4: Valor 2023 | H4: Valor 2024 | I4: Valor 2025 | J4: Dispara 2023 | K4: Dispara 2024 | L4: Dispara 2025 | M4: Alerta? | N4: Anos | O4: Relevância | P4: Nº alerta | Q4: Evidência (gerada por fórmula) | R4: Ponto a investigar | S4: Pergunta-modelo para a empresa | T4: Documento a pedir | U4: Por que importa | V4: Regra disparada (texto)
A5: R01 | B5: Receitas | C5: Maior cliente acima do limite | D5: Vendas do maior cliente / vendas | E5: acima do limite | F5: 0.2 | G5: =Métricas!C12 -> 0.15460526 | H5: =Métricas!D12 -> 0.15597484 | I5: =Métricas!E12 -> 0.15688623 | J5: =IF(ISNUMBER(G5),IF(G5>$F5,"Sim","Não"),"n.d.") -> Não | K5: =IF(ISNUMBER(H5),IF(H5>$F5,"Sim","Não"),"n.d.") -> Não | L5: =IF(ISNUMBER(I5),IF(I5>$F5,"Sim","Não"),"n.d.") -> Não | M5: =IF(COUNTIF(J5:L5,"Sim")>0,"Sim","Não") -> Não | N5: =MID(IF(J5="Sim",", 2023","")&IF(K5="Sim",", 2024","")&IF(L5="Sim",", 2025",""),3,20) | O5: Alta | P5: =IF(M5="Sim",COUNTIF(M$5:M5,"Sim"),"") | Q5: =IFERROR("Maior cliente em % das vendas — "&"2023: "&ROUND(Métricas!C12*100,1)&"%"&"; 2024: "&ROUND(Métricas!D12*100,1)&"%"&"; 2025: "&ROUND(Métricas!E12*100,1)&"%"&" ("&Métricas!E13&" em 2025). Fonte: "&Input!$F$6&"; "&Input!$F$49&" e seguintes","Ver folha Métricas") -> Maior cliente em % das vendas — 2023: 15,5%; 2024: 15,6%; 2025: 15,7% (Cliente A em 2025). Fonte: DRE!B5:D5; Vendas por Cliente!C5:G5 e seguintes | R5: Dependência de um cliente: risco de perda e de pressão sobre preços. | S5: Há contrato de longo prazo com este cliente? Com que prazo, preços e cláusula de mudança de controlo (change of control)? | T5: Contrato com o cliente; vendas e margem mensais por cliente | U5: Perder um cliente grande muda o valor da empresa; uma cláusula de change of control pode deixá-lo sair após a compra. | V5: ="R01"&" · "&C5&" (limite: "&ROUND(F5*100,0)&"%"&")" -> R01 · Maior cliente acima do limite (limite: 20%)
A6: R02 | B6: Receitas | C6: Cliente novo com peso relevante nas vendas | D6: Vendas a clientes sem vendas no ano anterior / vendas | E6: acima do limite | F6: 0.05 | G6: =Métricas!C9 -> n.d. | H6: =Métricas!D9 -> 0.014465409 | I6: =Métricas!E9 -> 0 | J6: =IF(ISNUMBER(G6),IF(G6>$F6,"Sim","Não"),"n.d.") -> n.d. | K6: =IF(ISNUMBER(H6),IF(H6>$F6,"Sim","Não"),"n.d.") -> Não | L6: =IF(ISNUMBER(I6),IF(I6>$F6,"Sim","Não"),"n.d.") -> Não | M6: =IF(COUNTIF(J6:L6,"Sim")>0,"Sim","Não") -> Não | N6: =MID(IF(J6="Sim",", 2023","")&IF(K6="Sim",", 2024","")&IF(L6="Sim",", 2025",""),3,20) | O6: Alta | P6: =IF(M6="Sim",COUNTIF(M$5:M6,"Sim"),"") | Q6: =IFERROR("Clientes novos em 2025: "&ROUND(Métricas!E9*100,1)&"%"&" das vendas ("&Métricas!E10&", "&ROUND(Métricas!E8,0)&"). Vendas: +"&ROUND(Métricas!E7*100,1)&"%"&"; sem clientes novos: "&ROUND(Métricas!E11*100,1)&"%"&". Fonte: "&Input!$F$49&" e seguintes","Ver folha Métricas") -> Clientes novos em 2025: 0% das vendas (—, 0). Vendas: +5%; sem clientes novos: 5%. Fonte: Vendas por Cliente!C5:G5 e seguintes | R6: Crescimento que pode vir de uma venda pontual e não da carteira recorrente. | S6: As vendas a este cliente repetem-se? Qual a natureza do contrato, o prazo e o que está previsto para o próximo ano? | T6: Contrato e faturas do cliente; carteira de encomendas | U6: O comprador paga por receita que se repete; uma venda pontual infla o crescimento e o EBITDA. | V6: ="R02"&" · "&C6&" (limite: "&ROUND(F6*100,0)&"%"&")" -> R02 · Cliente novo com peso relevante nas vendas (limite: 5%)
A7: R03 | B7: Margens | C7: Variação forte da margem bruta | D7: Margem bruta do ano − ano anterior (p.p.) | E7: variação acima do limite | F7: 3 | G7: =Métricas!C18 -> n.d. | H7: =Métricas!D18 -> 0.39622642 | I7: =Métricas!E18 -> -0.49802282 | J7: =IF(ISNUMBER(G7),IF(ABS(G7)>$F7,"Sim","Não"),"n.d.") -> n.d. | K7: =IF(ISNUMBER(H7),IF(ABS(H7)>$F7,"Sim","Não"),"n.d.") -> Não | L7: =IF(ISNUMBER(I7),IF(ABS(I7)>$F7,"Sim","Não"),"n.d.") -> Não | M7: =IF(COUNTIF(J7:L7,"Sim")>0,"Sim","Não") -> Não | N7: =MID(IF(J7="Sim",", 2023","")&IF(K7="Sim",", 2024","")&IF(L7="Sim",", 2025",""),3,20) | O7: Alta | P7: =IF(M7="Sim",COUNTIF(M$5:M7,"Sim"),"") | Q7: =IFERROR("Margem bruta — "&"2023: "&ROUND(Métricas!C17*100,1)&"%"&"; 2024: "&ROUND(Métricas!D17*100,1)&"%"&"; 2025: "&ROUND(Métricas!E17*100,1)&"%"&" (variação em 2025: "&ROUND(Métricas!E18,1)&" p.p.). Fonte: "&Input!$F$6&"; "&Input!$F$7,"Ver folha Métricas") -> Margem bruta — 2023: 28%; 2024: 28,4%; 2025: 27,9% (variação em 2025: -0,5 p.p.). Fonte: DRE!B5:D5; DRE!B6:D6 | R7: O que mudou nos preços, no mix de produtos ou nos custos de compra. | S7: O que explica a variação da margem bruta: preços de venda, mix de produtos, custos de compra ou descontos a clientes específicos? | T7: Margem por cliente e por linha de produto; tabelas de preços | U7: Cada ponto de margem bruta muda diretamente o EBITDA; se a variação for estrutural, o EBITDA futuro muda. | V7: ="R03"&" · "&C7&" (limite: "&F7&" p.p."&")" -> R03 · Variação forte da margem bruta (limite: 3 p.p.)
A8: R04 | B8: Qualidade do EBITDA | C8: Outros rendimentos relevantes dentro do EBITDA | D8: Outros rendimentos / vendas | E8: acima do limite | F8: 0.01 | G8: =Métricas!C21 -> 0.0039473684 | H8: =Métricas!D21 -> 0.0034591195 | I8: =Métricas!E21 -> 0.0038922156 | J8: =IF(ISNUMBER(G8),IF(G8>$F8,"Sim","Não"),"n.d.") -> Não | K8: =IF(ISNUMBER(H8),IF(H8>$F8,"Sim","Não"),"n.d.") -> Não | L8: =IF(ISNUMBER(I8),IF(I8>$F8,"Sim","Não"),"n.d.") -> Não | M8: =IF(COUNTIF(J8:L8,"Sim")>0,"Sim","Não") -> Não | N8: =MID(IF(J8="Sim",", 2023","")&IF(K8="Sim",", 2024","")&IF(L8="Sim",", 2025",""),3,20) | O8: Alta | P8: =IF(M8="Sim",COUNTIF(M$5:M8,"Sim"),"") | Q8: =IFERROR("Outros rendimentos — 2023: "&ROUND(Input!C11,0)&"; 2024: "&ROUND(Input!D11,0)&"; 2025: "&ROUND(Input!E11,0)&" ("&ROUND(Métricas!E21*100,1)&"%"&" das vendas; variação de "&ROUND(Métricas!E22*100,1)&"%"&"). Fonte: "&Input!$F$11,"Ver folha Métricas") -> Outros rendimentos — 2023: 60; 2024: 55; 2025: 65 (0,4% das vendas; variação de 18,2%). Fonte: DRE!B11:D11 | R8: Ganhos pontuais (venda de ativos, subsídios, indemnizações) dentro do EBITDA. | S8: Qual o detalhe de outros rendimentos? Inclui ganhos com venda de ativos, subsídios ou outros itens que não se repetem? | T8: Razão (extrato) de outros rendimentos; documentos dos itens relevantes | U8: Um ganho que não se repete, dentro do EBITDA, aumenta o preço pago por algo que não volta a acontecer. | V8: ="R04"&" · "&C8&" (limite: "&ROUND(F8*100,0)&"%"&")" -> R04 · Outros rendimentos relevantes dentro do EBITDA (limite: 1%)
A9: R05 | B9: Qualidade do EBITDA | C9: Ajustes da gestão elevados | D9: Ajustes / EBITDA reportado | E9: acima do limite | F9: 0.1 | G9: =Métricas!C28 -> 0.01899696 | H9: =Métricas!D28 -> 0.024305556 | I9: =Métricas!E28 -> 0.027605245 | J9: =IF(ISNUMBER(G9),IF(G9>$F9,"Sim","Não"),"n.d.") -> Não | K9: =IF(ISNUMBER(H9),IF(H9>$F9,"Sim","Não"),"n.d.") -> Não | L9: =IF(ISNUMBER(I9),IF(I9>$F9,"Sim","Não"),"n.d.") -> Não | M9: =IF(COUNTIF(J9:L9,"Sim")>0,"Sim","Não") -> Não | N9: =MID(IF(J9="Sim",", 2023","")&IF(K9="Sim",", 2024","")&IF(L9="Sim",", 2025",""),3,20) | O9: Alta | P9: =IF(M9="Sim",COUNTIF(M$5:M9,"Sim"),"") | Q9: =IFERROR("Ajustes em % do EBITDA reportado — "&"2023: "&ROUND(Métricas!C28*100,1)&"%"&"; 2024: "&ROUND(Métricas!D28*100,1)&"%"&"; 2025: "&ROUND(Métricas!E28*100,1)&"%"&". EBITDA 2025: reportado "&ROUND(Métricas!E19,0)&", ajustado pela gestão "&ROUND(Métricas!E27,0)&". Fonte: "&Input!$F$64&" e seguintes; "&Input!$F$6,"Ver folha Métricas") -> Ajustes em % do EBITDA reportado — 2023: 1,9%; 2024: 2,4%; 2025: 2,8%. EBITDA 2025: reportado 1449, ajustado pela gestão 1489. Fonte: EBITDA Ajustado!B8:D8 e seguintes; DRE!B5:D5 | R9: Se os ajustes são de facto não recorrentes e têm prova. | S9: Que documentos sustentam cada ajuste? Por que cada custo é considerado não recorrente? | T9: Faturas e contratos de cada ajuste | U9: O EBITDA ajustado é a base do preço; cada ajuste sem prova passa valor do comprador para o vendedor. | V9: ="R05"&" · "&C9&" (limite: "&ROUND(F9*100,0)&"%"&")" -> R05 · Ajustes da gestão elevados (limite: 10%)
A10: R06 | B10: Qualidade do EBITDA | C10: Ajuste 'não recorrente' que se repete todos os anos | D10: Nº de ajustes com valor nos 3 anos | E10: acima do limite | F10: 0 | G10: =Métricas!C29 -> n.d. | H10: =Métricas!D29 -> n.d. | I10: =Métricas!E29 -> 0 | J10: =IF(ISNUMBER(G10),IF(G10>$F10,"Sim","Não"),"n.d.") -> n.d. | K10: =IF(ISNUMBER(H10),IF(H10>$F10,"Sim","Não"),"n.d.") -> n.d. | L10: =IF(ISNUMBER(I10),IF(I10>$F10,"Sim","Não"),"n.d.") -> Não | M10: =IF(COUNTIF(J10:L10,"Sim")>0,"Sim","Não") -> Não | N10: =MID(IF(J10="Sim",", 2023","")&IF(K10="Sim",", 2024","")&IF(L10="Sim",", 2025",""),3,20) | O10: Média | P10: =IF(M10="Sim",COUNTIF(M$5:M10,"Sim"),"") | Q10: =IFERROR(ROUND(Métricas!E29,0)&" ajuste(s) aparece(m) em 2023, 2024 e 2025 (ex.: "&Métricas!E30&"). Fonte: "&Input!$F$64&" e seguintes","Ver folha Métricas") -> 0 ajuste(s) aparece(m) em 2023, 2024 e 2025 (ex.: —). Fonte: EBITDA Ajustado!B8:D8 e seguintes | R10: Custos classificados como não recorrentes que, na prática, são recorrentes. | S10: Por que este custo aparece todos os anos? O que garante que não se repetirá? | T10: Detalhe do ajuste por ano; plano e custos do programa associado | U10: Um custo que se repete é recorrente: não deve ser somado ao EBITDA. | V10: ="R06"&" · "&C10&" (limite: "&"mais de "&F10&")" -> R06 · Ajuste 'não recorrente' que se repete todos os anos (limite: mais de 0)
A11: R07 | B11: Capital de giro | C11: Contas a receber crescem acima das vendas | D11: Crescimento de clientes − crescimento das vendas (p.p.) | E11: acima do limite | F11: 10 | G11: =Métricas!C33 -> n.d. | H11: =Métricas!D33 -> -0.035162461 | I11: =Métricas!E33 -> 0.15373864 | J11: =IF(ISNUMBER(G11),IF(G11>$F11,"Sim","Não"),"n.d.") -> n.d. | K11: =IF(ISNUMBER(H11),IF(H11>$F11,"Sim","Não"),"n.d.") -> Não | L11: =IF(ISNUMBER(I11),IF(I11>$F11,"Sim","Não"),"n.d.") -> Não | M11: =IF(COUNTIF(J11:L11,"Sim")>0,"Sim","Não") -> Não | N11: =MID(IF(J11="Sim",", 2023","")&IF(K11="Sim",", 2024","")&IF(L11="Sim",", 2025",""),3,20) | O11: Alta | P11: =IF(M11="Sim",COUNTIF(M$5:M11,"Sim"),"") | Q11: =IFERROR("Clientes +"&ROUND(Métricas!E32*100,1)&"%"&" vs. vendas +"&ROUND(Métricas!E7*100,1)&"%"&" em 2025 (diferença de "&ROUND(Métricas!E33,1)&" p.p.; 2024: "&ROUND(Métricas!D33,1)&" p.p.). DSO: "&ROUND(Métricas!D34,1)&" → "&ROUND(Métricas!E34,1)&" dias. Fonte: "&Input!$F$22&"; "&Input!$F$6,"Ver folha Métricas") -> Clientes +5,2% vs. vendas +5% em 2025 (diferença de 0,2 p.p.; 2024: 0 p.p.). DSO: 62 → 62,1 dias. Fonte: Balanço!B9:E9; DRE!B5:D5 | R11: Possível deterioração dos recebimentos ou alargamento de prazos. | S11: Como evoluíram os prazos de pagamento e os saldos vencidos? Que clientes explicam o aumento? Houve alargamento de prazos? | T11: Aging de clientes nos dois últimos fechos; recebimentos após o fecho | U11: Vendas que não se recebem não geram caixa e podem esconder perdas futuras. | V11: ="R07"&" · "&C11&" (limite: "&F11&" p.p."&")" -> R07 · Contas a receber crescem acima das vendas (limite: 10 p.p.)
A12: R08 | B12: Capital de giro | C12: Aumento forte do prazo de recebimento | D12: DSO do ano − DSO do ano anterior (dias) | E12: acima do limite | F12: 15 | G12: =Métricas!C35 -> n.d. | H12: =Métricas!D35 -> -0.020841609 | I12: =Métricas!E35 -> 0.090724212 | J12: =IF(ISNUMBER(G12),IF(G12>$F12,"Sim","Não"),"n.d.") -> n.d. | K12: =IF(ISNUMBER(H12),IF(H12>$F12,"Sim","Não"),"n.d.") -> Não | L12: =IF(ISNUMBER(I12),IF(I12>$F12,"Sim","Não"),"n.d.") -> Não | M12: =IF(COUNTIF(J12:L12,"Sim")>0,"Sim","Não") -> Não | N12: =MID(IF(J12="Sim",", 2023","")&IF(K12="Sim",", 2024","")&IF(L12="Sim",", 2025",""),3,20) | O12: Média | P12: =IF(M12="Sim",COUNTIF(M$5:M12,"Sim"),"") | Q12: =IFERROR("DSO — "&"2023: "&ROUND(Métricas!C34,1)&"; 2024: "&ROUND(Métricas!D34,1)&"; 2025: "&ROUND(Métricas!E34,1)&" dias. Fonte: "&Input!$F$22&"; "&Input!$F$6,"Ver folha Métricas") -> DSO — 2023: 62; 2024: 62; 2025: 62,1 dias. Fonte: Balanço!B9:E9; DRE!B5:D5 | R12: Clientes a pagar mais tarde. | S12: Por que os clientes estão a pagar mais tarde? Houve mudança de condições de crédito? | T12: Aging de clientes; condições de crédito por cliente | U12: Prazos maiores prendem caixa e aumentam o risco de incobráveis. | V12: ="R08"&" · "&C12&" (limite: "&F12&" dias"&")" -> R08 · Aumento forte do prazo de recebimento (limite: 15 dias)
A13: R09 | B13: Capital de giro | C13: Inventários crescem acima do CMV | D13: Crescimento dos inventários − crescimento do CMV (p.p.) | E13: acima do limite | F13: 10 | G13: =Métricas!C38 -> n.d. | H13: =Métricas!D38 -> -0.029605263 | I13: =Métricas!E38 -> -0.20641195 | J13: =IF(ISNUMBER(G13),IF(G13>$F13,"Sim","Não"),"n.d.") -> n.d. | K13: =IF(ISNUMBER(H13),IF(H13>$F13,"Sim","Não"),"n.d.") -> Não | L13: =IF(ISNUMBER(I13),IF(I13>$F13,"Sim","Não"),"n.d.") -> Não | M13: =IF(COUNTIF(J13:L13,"Sim")>0,"Sim","Não") -> Não | N13: =MID(IF(J13="Sim",", 2023","")&IF(K13="Sim",", 2024","")&IF(L13="Sim",", 2025",""),3,20) | O13: Média | P13: =IF(M13="Sim",COUNTIF(M$5:M13,"Sim"),"") | Q13: =IFERROR("Inventários +"&ROUND(Métricas!E36*100,1)&"%"&" vs. CMV +"&ROUND(Métricas!E37*100,1)&"%"&" em 2025 (diferença de "&ROUND(Métricas!E38,1)&" p.p.). DIO: "&ROUND(Métricas!D39,1)&" → "&ROUND(Métricas!E39,1)&" dias. Fonte: "&Input!$F$21&"; "&Input!$F$7,"Ver folha Métricas") -> Inventários +5,6% vs. CMV +5,8% em 2025 (diferença de -0,2 p.p.). DIO: 75 → 74,9 dias. Fonte: Balanço!B8:E8; DRE!B6:D6 | R13: Stock parado ou obsoleto; compras acima das necessidades. | S13: Qual a composição e a antiguidade dos stocks? Que encomendas justificam o nível atual? Qual a política de imparidades? | T13: Aging de inventários; artigos sem movimento; carteira de encomendas | U13: Stock parado prende caixa e pode valer menos do que o registado. | V13: ="R09"&" · "&C13&" (limite: "&F13&" p.p."&")" -> R09 · Inventários crescem acima do CMV (limite: 10 p.p.)
A14: R10 | B14: Geração de caixa | C14: Fraca conversão do EBITDA em caixa | D14: Caixa gerada pelas operações / EBITDA | E14: abaixo do limite | F14: 0.7 | G14: =Métricas!C44 -> 0.90729483 | H14: =Métricas!D44 -> 0.91111111 | I14: =Métricas!E44 -> 0.89302968 | J14: =IF(ISNUMBER(G14),IF(G14<$F14,"Sim","Não"),"n.d.") -> Não | K14: =IF(ISNUMBER(H14),IF(H14<$F14,"Sim","Não"),"n.d.") -> Não | L14: =IF(ISNUMBER(I14),IF(I14<$F14,"Sim","Não"),"n.d.") -> Não | M14: =IF(COUNTIF(J14:L14,"Sim")>0,"Sim","Não") -> Não | N14: =MID(IF(J14="Sim",", 2023","")&IF(K14="Sim",", 2024","")&IF(L14="Sim",", 2025",""),3,20) | O14: Alta | P14: =IF(M14="Sim",COUNTIF(M$5:M14,"Sim"),"") | Q14: =IFERROR("Conversão de caixa — "&"2023: "&ROUND(Métricas!C44*100,1)&"%"&"; 2024: "&ROUND(Métricas!D44*100,1)&"%"&"; 2025: "&ROUND(Métricas!E44*100,1)&"%"&". FCO 2025: "&ROUND(Métricas!E45,0)&". Fonte: "&Input!$F$40&"; "&Input!$F$6,"Ver folha Métricas") -> Conversão de caixa — 2023: 90,7%; 2024: 91,1%; 2025: 89,3%. FCO 2025: 985. Fonte: DFC!B15:D15; DRE!B5:D5 | R14: EBITDA que não se transforma em caixa. | S14: Por que o EBITDA não se converteu em caixa? Que rubricas de capital de giro explicam a diferença? | T14: Reconciliação entre EBITDA e caixa; mapa mensal de capital de giro | U14: O comprador avalia a empresa pelo caixa que ela gera. | V14: ="R10"&" · "&C14&" (limite: "&ROUND(F14*100,0)&"%"&")" -> R10 · Fraca conversão do EBITDA em caixa (limite: 70%)
A15: R11 | B15: Dívida | C15: Dívida concentrada nos próximos 12 meses | D15: Financiamentos correntes / dívida financeira | E15: acima do limite | F15: 0.4 | G15: =Métricas!C50 -> 0.17647059 | H15: =Métricas!D50 -> 0.21428571 | I15: =Métricas!E50 -> 0.27272727 | J15: =IF(ISNUMBER(G15),IF(G15>$F15,"Sim","Não"),"n.d.") -> Não | K15: =IF(ISNUMBER(H15),IF(H15>$F15,"Sim","Não"),"n.d.") -> Não | L15: =IF(ISNUMBER(I15),IF(I15>$F15,"Sim","Não"),"n.d.") -> Não | M15: =IF(COUNTIF(J15:L15,"Sim")>0,"Sim","Não") -> Não | N15: =MID(IF(J15="Sim",", 2023","")&IF(K15="Sim",", 2024","")&IF(L15="Sim",", 2025",""),3,20) | O15: Alta | P15: =IF(M15="Sim",COUNTIF(M$5:M15,"Sim"),"") | Q15: =IFERROR("Dívida a vencer em 12 meses — "&"2023: "&ROUND(Métricas!C50*100,1)&"%"&"; 2024: "&ROUND(Métricas!D50*100,1)&"%"&"; 2025: "&ROUND(Métricas!E50*100,1)&"%"&" ("&ROUND(Input!E30,0)&" de "&ROUND(Métricas!E49,0)&" em 2025). Fonte: "&Input!$F$30&"; "&Input!$F$27,"Ver folha Métricas") -> Dívida a vencer em 12 meses — 2023: 17,6%; 2024: 21,4%; 2025: 27,3% (360 de 1320 em 2025). Fonte: Balanço!B23:E23; Balanço!B20:E20 | R15: Necessidade de refinanciamento. | S15: Existem linhas contratadas ou negociações de refinanciamento em curso? Em que condições? | T15: Contratos de financiamento; propostas dos bancos; certificados de covenants | U15: Sem refinanciamento, a empresa pode não conseguir pagar a dívida que vence. | V15: ="R11"&" · "&C15&" (limite: "&ROUND(F15*100,0)&"%"&")" -> R11 · Dívida concentrada nos próximos 12 meses (limite: 40%)
A16: R12 | B16: Consistência | C16: Balanço não fecha | D16: Ativo − (capital próprio + passivo) | E16: variação acima do limite | F16: 1 | G16: =Métricas!C58 -> 0 | H16: =Métricas!D58 -> 0 | I16: =Métricas!E58 -> 0 | J16: =IF(ISNUMBER(G16),IF(ABS(G16)>$F16,"Sim","Não"),"n.d.") -> Não | K16: =IF(ISNUMBER(H16),IF(ABS(H16)>$F16,"Sim","Não"),"n.d.") -> Não | L16: =IF(ISNUMBER(I16),IF(ABS(I16)>$F16,"Sim","Não"),"n.d.") -> Não | M16: =IF(COUNTIF(J16:L16,"Sim")>0,"Sim","Não") -> Não | N16: =MID(IF(J16="Sim",", 2023","")&IF(K16="Sim",", 2024","")&IF(L16="Sim",", 2025",""),3,20) | O16: Alta | P16: =IF(M16="Sim",COUNTIF(M$5:M16,"Sim"),"") | Q16: =IFERROR("Diferença no balanço — "&"2023: "&ROUND(Métricas!C58,0)&"; 2024: "&ROUND(Métricas!D58,0)&"; 2025: "&ROUND(Métricas!E58,0)&". Fonte: Input, secção Balanço","Ver folha Métricas") -> Diferença no balanço — 2023: 0; 2024: 0; 2025: 0. Fonte: Input, secção Balanço | R16: Erro nas demonstrações financeiras. | S16: Qual a versão correta do balanço? | T16: Balancete e balanço finais | U16: Um balanço que não fecha invalida as análises que dependem dele. | V16: ="R12"&" · "&C16&" (limite: "&F16&" mil €"&")" -> R12 · Balanço não fecha (limite: 1 mil €)
A17: R13 | B17: Consistência | C17: Caixa da DFC não bate com o balanço | D17: Caixa final da DFC − caixa do balanço | E17: variação acima do limite | F17: 1 | G17: =Métricas!C59 -> 0 | H17: =Métricas!D59 -> 0 | I17: =Métricas!E59 -> 0 | J17: =IF(ISNUMBER(G17),IF(ABS(G17)>$F17,"Sim","Não"),"n.d.") -> Não | K17: =IF(ISNUMBER(H17),IF(ABS(H17)>$F17,"Sim","Não"),"n.d.") -> Não | L17: =IF(ISNUMBER(I17),IF(ABS(I17)>$F17,"Sim","Não"),"n.d.") -> Não | M17: =IF(COUNTIF(J17:L17,"Sim")>0,"Sim","Não") -> Não | N17: =MID(IF(J17="Sim",", 2023","")&IF(K17="Sim",", 2024","")&IF(L17="Sim",", 2025",""),3,20) | O17: Média | P17: =IF(M17="Sim",COUNTIF(M$5:M17,"Sim"),"") | Q17: =IFERROR("Caixa final da DFC − caixa do balanço — "&"2023: "&ROUND(Métricas!C59,0)&"; 2024: "&ROUND(Métricas!D59,0)&"; 2025: "&ROUND(Métricas!E59,0)&". Fonte: "&Input!$F$46&"; "&Input!$F$24,"Ver folha Métricas") -> Caixa final da DFC − caixa do balanço — 2023: 0; 2024: 0; 2025: 0. Fonte: DFC!B31:D31; Balanço!B11:E11 | R17: Erro na DFC ou no balanço. | S17: Qual é o valor correto? A DFC é a versão auditada? Há outros erros na informação? | T17: DFC corrigida; relatório de auditoria | U17: Um erro simples põe em dúvida a qualidade de toda a informação financeira. | V17: ="R13"&" · "&C17&" (limite: "&F17&" mil €"&")" -> R13 · Caixa da DFC não bate com o balanço (limite: 1 mil €)
A18: R14 | B18: Consistência | C18: Variações de capital de giro da DFC não batem com o balanço | D18: Soma das diferenças nas 5 linhas de capital de giro | E18: variação acima do limite | F18: 1 | G18: =Métricas!C60 -> 0 | H18: =Métricas!D60 -> 0 | I18: =Métricas!E60 -> 0 | J18: =IF(ISNUMBER(G18),IF(ABS(G18)>$F18,"Sim","Não"),"n.d.") -> Não | K18: =IF(ISNUMBER(H18),IF(ABS(H18)>$F18,"Sim","Não"),"n.d.") -> Não | L18: =IF(ISNUMBER(I18),IF(ABS(I18)>$F18,"Sim","Não"),"n.d.") -> Não | M18: =IF(COUNTIF(J18:L18,"Sim")>0,"Sim","Não") -> Não | N18: =MID(IF(J18="Sim",", 2023","")&IF(K18="Sim",", 2024","")&IF(L18="Sim",", 2025",""),3,20) | O18: Média | P18: =IF(M18="Sim",COUNTIF(M$5:M18,"Sim"),"") | Q18: =IFERROR("Diferença entre DFC e balanço nas variações de capital de giro — "&"2023: "&ROUND(Métricas!C60,0)&"; 2024: "&ROUND(Métricas!D60,0)&"; 2025: "&ROUND(Métricas!E60,0)&". Fonte: "&Input!$F$35&" a "&Input!$F$39,"Ver folha Métricas") -> Diferença entre DFC e balanço nas variações de capital de giro — 2023: 0; 2024: 0; 2025: 0. Fonte: DFC!B10:D10 a DFC!B14:D14 | R18: Linha da DFC preenchida com o valor errado. | S18: Qual a variação correta de cada rubrica de capital de giro? | T18: DFC corrigida; balancetes de abertura e fecho | U18: Se a DFC estiver errada, a conversão de caixa também está. | V18: ="R14"&" · "&C18&" (limite: "&F18&" mil €"&")" -> R14 · Variações de capital de giro da DFC não batem com o balanço (limite: 1 mil €)
A19: R15 | B19: Consistência | C19: Resultado líquido diferente entre demonstrações | D19: Maior diferença entre DRE, balanço e DFC | E19: variação acima do limite | F19: 1 | G19: =Métricas!C61 -> 0 | H19: =Métricas!D61 -> 0 | I19: =Métricas!E61 -> 0 | J19: =IF(ISNUMBER(G19),IF(ABS(G19)>$F19,"Sim","Não"),"n.d.") -> Não | K19: =IF(ISNUMBER(H19),IF(ABS(H19)>$F19,"Sim","Não"),"n.d.") -> Não | L19: =IF(ISNUMBER(I19),IF(ABS(I19)>$F19,"Sim","Não"),"n.d.") -> Não | M19: =IF(COUNTIF(J19:L19,"Sim")>0,"Sim","Não") -> Não | N19: =MID(IF(J19="Sim",", 2023","")&IF(K19="Sim",", 2024","")&IF(L19="Sim",", 2025",""),3,20) | O19: Alta | P19: =IF(M19="Sim",COUNTIF(M$5:M19,"Sim"),"") | Q19: =IFERROR("Diferença no resultado líquido — "&"2023: "&ROUND(Métricas!C61,0)&"; 2024: "&ROUND(Métricas!D61,0)&"; 2025: "&ROUND(Métricas!E61,0)&". Fonte: "&Input!$F$16&"; "&Input!$F$26&"; "&Input!$F$34,"Ver folha Métricas") -> Diferença no resultado líquido — 2023: 0; 2024: 0; 2025: 0. Fonte: DRE!B19:D19; Balanço!B18:E18; DFC!B5:D5 | R19: Demonstrações de versões diferentes. | S19: Qual é o resultado líquido correto de cada ano? | T19: Contas finais aprovadas | U19: Demonstrações que não batem podem vir de versões diferentes das contas. | V19: ="R15"&" · "&C19&" (limite: "&F19&" mil €"&")" -> R15 · Resultado líquido diferente entre demonstrações (limite: 1 mil €)
A20: R16 | B20: Consistência | C20: Vendas por cliente não somam as vendas da DRE | D20: Soma das vendas por cliente − vendas da DRE | E20: variação acima do limite | F20: 1 | G20: =Métricas!C62 -> 0 | H20: =Métricas!D62 -> 0 | I20: =Métricas!E62 -> 0 | J20: =IF(ISNUMBER(G20),IF(ABS(G20)>$F20,"Sim","Não"),"n.d.") -> Não | K20: =IF(ISNUMBER(H20),IF(ABS(H20)>$F20,"Sim","Não"),"n.d.") -> Não | L20: =IF(ISNUMBER(I20),IF(ABS(I20)>$F20,"Sim","Não"),"n.d.") -> Não | M20: =IF(COUNTIF(J20:L20,"Sim")>0,"Sim","Não") -> Não | N20: =MID(IF(J20="Sim",", 2023","")&IF(K20="Sim",", 2024","")&IF(L20="Sim",", 2025",""),3,20) | O20: Média | P20: =IF(M20="Sim",COUNTIF(M$5:M20,"Sim"),"") | Q20: =IFERROR("Vendas por cliente − vendas da DRE — "&"2023: "&ROUND(Métricas!C62,0)&"; 2024: "&ROUND(Métricas!D62,0)&"; 2025: "&ROUND(Métricas!E62,0)&". Fonte: Input, secção Vendas por cliente","Ver folha Métricas") -> Vendas por cliente − vendas da DRE — 2023: 0; 2024: 0; 2025: 0. Fonte: Input, secção Vendas por cliente | R20: Listagem de clientes incompleta ou de outra base. | S20: Por que a listagem de vendas por cliente não bate com a DRE? | T20: Extração de vendas por cliente reconciliada com a contabilidade | U20: As análises de concentração só valem se a base bater com as contas. | V20: ="R16"&" · "&C20&" (limite: "&F20&" mil €"&")" -> R16 · Vendas por cliente não somam as vendas da DRE (limite: 1 mil €)
A21: R17 | B21: Consistência | C21: Mapa da dívida não bate com o balanço | D21: Diferença no total e na parcela corrente | E21: variação acima do limite | F21: 1 | G21: =Métricas!C63 -> n.d. | H21: =Métricas!D63 -> n.d. | I21: =Métricas!E63 -> 0 | J21: =IF(ISNUMBER(G21),IF(ABS(G21)>$F21,"Sim","Não"),"n.d.") -> n.d. | K21: =IF(ISNUMBER(H21),IF(ABS(H21)>$F21,"Sim","Não"),"n.d.") -> n.d. | L21: =IF(ISNUMBER(I21),IF(ABS(I21)>$F21,"Sim","Não"),"n.d.") -> Não | M21: =IF(COUNTIF(J21:L21,"Sim")>0,"Sim","Não") -> Não | N21: =MID(IF(J21="Sim",", 2023","")&IF(K21="Sim",", 2024","")&IF(L21="Sim",", 2025",""),3,20) | O21: Média | P21: =IF(M21="Sim",COUNTIF(M$5:M21,"Sim"),"") | Q21: =IFERROR("Mapa da dívida − balanço em 2025: "&ROUND(Métricas!E63,0)&". Fonte: "&Input!$F$71&"; "&Input!$F$30,"Ver folha Métricas") -> Mapa da dívida − balanço em 2025: 0. Fonte: Dívida!D7; Balanço!B23:E23 | R21: Dívida em falta no mapa ou no balanço. | S21: Que financiamentos explicam a diferença entre o mapa e o balanço? | T21: Mapa da dívida reconciliado; extratos bancários | U21: Dívida não identificada reduz diretamente o valor para o acionista. | V21: ="R17"&" · "&C21&" (limite: "&F21&" mil €"&")" -> R17 · Mapa da dívida não bate com o balanço (limite: 1 mil €)
A22: R18 | B22: Informação | C22: Documentos obrigatórios em falta | D22: Nº de documentos marcados com 'Não' | E22: acima do limite | F22: 0 | G22: =Métricas!C65 -> n.d. | H22: =Métricas!D65 -> n.d. | I22: =Métricas!E65 -> 0 | J22: =IF(ISNUMBER(G22),IF(G22>$F22,"Sim","Não"),"n.d.") -> n.d. | K22: =IF(ISNUMBER(H22),IF(H22>$F22,"Sim","Não"),"n.d.") -> n.d. | L22: =IF(ISNUMBER(I22),IF(I22>$F22,"Sim","Não"),"n.d.") -> Não | M22: =IF(COUNTIF(J22:L22,"Sim")>0,"Sim","Não") -> Não | N22: =MID(IF(J22="Sim",", 2023","")&IF(K22="Sim",", 2024","")&IF(L22="Sim",", 2025",""),3,20) | O22: Média | P22: =IF(M22="Sim",COUNTIF(M$5:M22,"Sim"),"") | Q22: =IFERROR(ROUND(Métricas!E65,0)&" documento(s) em falta: "&Métricas!E66&". Fonte: Input, Documentos recebidos","Ver folha Métricas") -> 0 documento(s) em falta: —. Fonte: Input, Documentos recebidos | R22: Sem estes documentos, alguns alertas não podem ser confirmados nem afastados. | S22: Podem enviar os documentos em falta? | T22: Os documentos listados na evidência | U22: O que falta também é um ponto de atenção: limita o que o comprador pode verificar. | V22: ="R18"&" · "&C22&" (limite: "&"mais de "&F22&")" -> R18 · Documentos obrigatórios em falta (limite: mais de 0)
A23: R19 | B23: Qualidade do EBITDA | C23: Ganho na venda de ativos dentro do EBITDA | D23: Ganhos na alienação de ativos / EBITDA reportado | E23: acima do limite | F23: 0.05 | G23: =Métricas!C24 -> 0 | H23: =Métricas!D24 -> 0 | I23: =Métricas!E24 -> 0.0034506556 | J23: =IF(ISNUMBER(G23),IF(G23>$F23,"Sim","Não"),"n.d.") -> Não | K23: =IF(ISNUMBER(H23),IF(H23>$F23,"Sim","Não"),"n.d.") -> Não | L23: =IF(ISNUMBER(I23),IF(I23>$F23,"Sim","Não"),"n.d.") -> Não | M23: =IF(COUNTIF(J23:L23,"Sim")>0,"Sim","Não") -> Não | N23: =MID(IF(J23="Sim",", 2023","")&IF(K23="Sim",", 2024","")&IF(L23="Sim",", 2025",""),3,20) | O23: Alta | P23: =IF(M23="Sim",COUNTIF(M$5:M23,"Sim"),"") | Q23: =IFERROR("Ganhos na alienação de ativos — 2023: "&ROUND(Métricas!C23,0)&"; 2024: "&ROUND(Métricas!D23,0)&"; 2025: "&ROUND(Métricas!E23,0)&" ("&ROUND(Métricas!E24*100,1)&"%"&" do EBITDA). EBITDA de 2025 sem esses ganhos: "&ROUND(Métricas!E25,0)&". Fonte: "&Input!$F$44&"; "&Input!$F$11,"Ver folha Métricas") -> Ganhos na alienação de ativos — 2023: 0; 2024: 0; 2025: 5 (0,3% do EBITDA). EBITDA de 2025 sem esses ganhos: 1444. Fonte: DFC!B9:D9; DRE!B11:D11 | R23: Ganho que não se repete a aumentar o EBITDA. | S23: Que ativos foram vendidos? Em que rubrica foi registado o ganho e está incluído no EBITDA apresentado? | T23: Contrato ou escritura de venda; registo contabilístico do ganho | U23: Um ganho de venda de ativos não se repete; dentro do EBITDA, o comprador pagaria por ele no múltiplo. | V23: ="R19"&" · "&C23&" (limite: "&ROUND(F23*100,0)&"%"&")" -> R19 · Ganho na venda de ativos dentro do EBITDA (limite: 5%)
A24: R20 | B24: Dívida | C24: Folga do covenant reduzida | D24: 1 − (dívida líquida / EBITDA) / limite do covenant | E24: abaixo do limite | F24: 0.15 | G24: =Métricas!C55 -> n.d. | H24: =Métricas!D55 -> n.d. | I24: =Métricas!E55 -> 0.82355648 | J24: =IF(ISNUMBER(G24),IF(G24<$F24,"Sim","Não"),"n.d.") -> n.d. | K24: =IF(ISNUMBER(H24),IF(H24<$F24,"Sim","Não"),"n.d.") -> n.d. | L24: =IF(ISNUMBER(I24),IF(I24<$F24,"Sim","Não"),"n.d.") -> Não | M24: =IF(COUNTIF(J24:L24,"Sim")>0,"Sim","Não") -> Não | N24: =MID(IF(J24="Sim",", 2023","")&IF(K24="Sim",", 2024","")&IF(L24="Sim",", 2025",""),3,20) | O24: Alta | P24: =IF(M24="Sim",COUNTIF(M$5:M24,"Sim"),"") | Q24: =IFERROR("Dívida líquida / EBITDA em 2025: "&ROUND(Métricas!E52,2)&"x (limite "&ROUND(Métricas!E54,1)&"x); folga de "&ROUND(Métricas!E55*100,1)&"%"&". EBITDA mínimo para cumprir: "&ROUND(Métricas!E56,0)&". Sem ganhos na alienação, o rácio é "&ROUND(Métricas!E53,2)&"x. Fonte: "&Input!$F$73&"; "&Input!$F$30,"Ver folha Métricas") -> Dívida líquida / EBITDA em 2025: 0,53x (limite 3x); folga de 82,4%. EBITDA mínimo para cumprir: 256. Sem ganhos na alienação, o rácio é 0,53x. Fonte: Dívida!I5 (empréstimo bancário, teste anual); Balanço!B23:E23 | R24: Risco de quebra do covenant se o EBITDA comparável for menor do que o reportado. | S24: Como o contrato define o EBITDA do covenant? Qual foi a folga nos últimos testes? Já houve pedidos de dispensa (waiver)? | T24: Contrato do empréstimo; certificados de cumprimento de covenants | U24: A quebra de um covenant pode tornar a dívida exigível de imediato e dá poder negocial aos bancos. | V24: ="R20"&" · "&C24&" (limite: "&ROUND(F24*100,0)&"%"&")" -> R20 · Folga do covenant reduzida (limite: 15%)
